Workbook

Sheet Studies_ID
A1: id_study | B1: study_name_public | C1: study_name_contracted | D1: leading_institution | E1: id_institution | F1: rationale | G1: key_findings | H1: study_sector | I1: study_status | J1: factsheet_name | K1: factsheet_link | L1: contract_dates | M1: contact_name_sc | N1: contact_name _pi | O1: study_type | P1: imeo_objective | Q1: ccac_imeo | R1: imeo_affiliation
A2: 8b52df97-e308-43cf-a656-6a7b607d599e | B2: Baseline Scoping Study of Emissions in Nigeria | D2: Queen Mary University of London, United Kingdom (Scoping phase) Harvard University, United States (Satellite component) | E2: cc378b2c-297b-4b02-abc2-a2adce9d439a | F2: Nigeria, like many countries, faces challenges in setting effective methane reduction targets and tracking progress due to a lack of measurement-based emissions data across sectors. As a Global Methane Pledge Champion, the country has demonstrated its leadership in methane reduction efforts, and is in great need of improved data to support this. | G2: The objective of the scoping study is to determine the availability of methane data, establish a research consortium, and develop a feasibility study and quantification plan for a full two-year Baseline Study in Nigeria. To proceed to the full Baseline Study, the proposal must be approved by IMEO’s Scientific Oversight Committee. The potential Nigeria Baseline Study would be the first multisector (oil and gas, waste and agriculture) scientific study of anthropogenic methane emission on the African continent, and one of the first in the world. | H2: Multisector | I2: Ongoing | J2: Baseline Scoping Study of Emissions in Nigeria | K2: Baseline Scoping Study of Emissions in Nigeria | M2: Xuefei Li | N2: Paul Balcombe | O2: Desktop analysis | P2: 4 | Q2: IMEO
A3: 2c366808-4f57-4ca6-a4f6-53f027e06258 | B3: Upscaling Methane Measurements and Verifying Emissions Inventories in the Netherlands | D3: Utrecht University, Netherlands | E3: d57ecf4e-49ec-4bec-83b1-78ff974f2792 | F3: A wide range of scientific measurements across methane emission sources exists in the Netherlands. This provides a valuable opportunity to synthesize existing data for a more complete picture of emissions nationally and across sources. The results can inform inventory efforts, identify the most essential measurements for reliable emissions' quantification, and provide a benchmark for other efforts to baseline emissions in other countries – especially developing nations with scarcer methane measurement data available. | G3: This study will upscale existing measurements, compare them to atmospheric observations, and provide a national baseline of emissions across sources in the Netherlands. | H3: Multisector | I3: Ongoing | J3: Upscaling Methane Measurements and Verifying Emissions Inventories in the Netherlands | K3: Upscaling Methane Measurements and Verifying Emissions Inventories in the Netherlands | M3: Xuefei Li | N3: Guus Velders | O3: Desktop analysis | P3: 1 | Q3: IMEO
A4: e9c628a6-f5fe-43a2-b4b5-49f5a7a736d9 | B4: Methane emissions baseline for livestock and rice systems in Colombia | D4: Alianza Bioversity-CIAT | E4: ec4a6016-97eb-4fb6-bde0-2c44a0e56ecf | F4: The project is expected to deliver a comprehensive CH4 baseline data for rice and livestock, incorporating literature reviews, ongoing project data, and direct measurements. It will provide representative CH4 emission factors, identify key livestock and rice systems requiring further assessment, and validate multi-scale measurement techniques to enhance accuracy. The final outputs will include a roadmap for targeted CH4 measurements, methodologies for national upscaling, and recommendations for strengthening Colombia’s CH4 inventory. These efforts will contribute to improved CH4 mitigation strategies, enabling Colombia to achieve its climate goals while supporting the IMEO Colombia Baseline Study’s broader objectives. | G4: The project will achieve several key targets. It will consolidate all available CH4 emissions data for livestock and rice systems in Colombia, including unpublished and gray literature sources, and map ongoing projects to create a comprehensive CH₄ data inventory. For livestock systems, measurement gaps will be identified through the development of a prioritized list of regions, production systems, and practices requiring direct CH4 measurements using innovative tools. In contrast, for rice systems, the focus will be on compiling and analyzing existing data rather than conducting new field measurements. The project will also assess activity data requirements and propose methodologies for national-level upscaling of CH4 emissions estimates for both sectors. A deployment plan will be developed for implementing advanced atmospheric measurement techniques for livestock systems, validated through multi-scale methods. Finally, the project will provide recommendations for enhancing Colombia’s national CH4 inventory, integrating validated measurement-based approaches for livestock and rice (Tier 2), to improve accuracy and policy relevance. | H4: Agriculture | I4: Ongoing | J4: Methane emissions baseline for livestock and rice systems in Colombia | M4: Xuefei Li | N4: Ciniro Costa | O4: Measurement Campaign | P4: 4 | Q4: IMEO
A5: 597480a2-041d-45bc-8b69-e4561b325381 | B5: Waste measurements for the Baseline Study of Emissions in Colombia | D5: Carleton University, Canada | E5: 561bf82a-557c-4655-958c-8684e9d78281 | H5: Waste & Wastewater | I5: Upcoming | M5: TBD | N5: Matthew Johnson | O5: Measurement Campaign | P5: 4 | Q5: IMEO
A6: 9cd4092d-b9ec-4921-8e92-60b94271f15f | B6: Madrid Landfill Methane Emission Quantification Comparison Study | D6: Technical University of Denmark | E6: 7c2e3b01-f867-4342-a795-01c14255ece1 | F6: Significant discrepancies have been found between emissions measurements and reporting around the Las Dehehas landfill near Madrid, Spain. Emissio rates exceeding multiple tons of methane per hour have been reported from previous satellite retrievals, an order of magnitude greater than landfill operator estimates. The study will take simultaneous, comparative measurements of landfill emission via satellites and ground-based techniques, which are crucial to reconcile bottom-up and top-down landfill methane emissions measurements. Measurements will be performed during multiple field and remore-sensing campaigns. | G6: In progress | H6: Waste & Wastewater | I6: Ongoing | J6: Madrid Landfill Methane Comparison | M6: Tarek Abichou - Malika Menoud | O6: Measurement Campaign | Q6: IMEO
A7: edf2fa58-6b25-42a8-a8b7-61db47fbb4cd | B7: Nord Stream Gas Leaks Synthesis | D7: IMEO | E7: 1fccc344-9f87-4fc2-94d8-353ea21dc19f | F7: The 2022 Nord Stream underwater pipeline explosions are thought to have caused one of the largest anthropogenic methane emission event ever recorded. Despite numerous individual assessments of its impact on the global atmospheric methane budget, there is high uncertainty as to the exact amount of methane released from the pipelines. The goal of this study was to compile and reconcile emissions estimates from the Nord Stream pipeline leaks to present a more accurate methane emission estimate from the incident. Furthermore, the report showcases the different measurement approaches available (marine, airborne, tall-tower and satellite-based), for quantifying methane emissions in similar contexts. Finally, it explains and contextualizes reported emissions to a wider scientific audience. | G7: By reconciling modelled atmospheric emissions with top-down emission estimates, the study concluded that the Nord Stream pipeline emitted 465±20 thousand metric tons of methane into the atmosphere between 26 September and 3 October 2022. Although this represents the largest recorded emission of methane to the atmosphere from a single transient event, this amount is equivalent to only 0.1 per cent of anthropogenic methane emissions for 2022. The synthesis report shows how diverse, complementary measurement approaches are most effective for quantifying more accurately methane emissions, the Nord Stream pipeline leaks being a case in point. | H7: Oil and Gas | I7: Completed | J7: Synthesis report on Nord Stream gas leaks | K7: Synthesis report on Nord Stream gas leaks | M7: Stephen Harris | N7: Stephen Harris | O7: Data Integration | P7: 1 | Q7: IMEO
A8: 7fbaef23-727c-4c26-b6de-5190343955f3 | B8: Airborne Measurements from the Nord Stream Gas Leaks | D8: German Aerospace Center, Germany | E8: f08df46e-5e65-428c-9b95-282da81080e1 | F8: The 2022 Nord Stream underwater pipeline explosions are thought to have caused one of the largest anthropogenic methane emission event ever recorded. A team led by IMEO conducted the first and only aerial measurement of the event to provide rapid direct assessment of its impact. The goal of the study was to quantify the short-lived methane emissions that occurred immediately after, and directly near, the Nord Stream leak sites. | G8: While most of the methane leaked from the pipelines escaped directly into the atmosphere between 26 September and 1 October 2022, a fraction dissolved in the Baltic Sea. The atmospheric measurements of methane acquired using HELiPOD revealed that, on 5 October 2022, sea-surface outgassing rates ranged from 19 to 48 metric tons per hour. These emission rates are of similar magnitude to those of the Upper Silesian Coal Basin, which is the largest anthropogenic source of methane in Europe. Satellites are not equipped to detect the diffuse (non-point source) methane emissions measured by HELiPOD, pointing to the importance of diversifying measurement tools and approaches to obtain more accurate emission data. The study findings broadly align with oceanic methane transport and dissolution models over the Baltic region and are proving crucial to verify the simulated emission rates presented as part of IMEO’s synthesis work on the Nord Stream pipeline leaks (Harris et al., under review). | H8: Oil and Gas | I8: Completed | J8: Airborne measurements from the Nord Stream gas leaks | K8: Airborne measurements from the Nord Stream gas leaks | M8: Stephen Harris | N8: Anke Roiger | O8: Measurement Campaign | P8: 1 | Q8: IMEO
A9: 25e348c0-c485-4f68-b882-c0d489e85e86 | B9: Offshore Measurement Study in Angola and Gabon | D9: German Aerospace Center, Germany | E9: f08df46e-5e65-428c-9b95-282da81080e1 | F9: The region is home to substantial oil and gas production by both national and international oil companies and has been identified as a flaring hotspot. Quantification of methane emissions from these offshore facilities are sparse. | G9: The MTGA study will provide a comprehensive dataset on methane emissions from the offshore oil and gas industry off the coast of Angola, and significantly enhance the understanding of emission sources and patterns in the region. | H9: Oil and Gas | I9: Completed | J9: Measuring offshore oil & gas emissions in Angola and Gabon | K9: Measuring offshore oil & gas emissions in Angola and Gabon | M9: Stephen Harris | N9: Alina Fiehn | O9: Measurement Campaign | P9: 1 | Q9: CCAC
A10: f4a28a88-e041-4d66-b09e-d80c363fbd86 | B10: Coal Mine Methane Emissions: Sources, Mitigation Potential, Monitoring and Emissions Quantification (Coal Phase I) | D10: Environmental Defense Fund, United States | E10: b8f497f5-5560-4f37-9d24-4d5d006bb999 | F10: The study assesses current literature and data on coal mine methane emissions as a foundation for future measurement-based studies of the sector. This study provides a state-of-the-art understanding of coal mine methane emissions with focus upon sources, mitigation approaches, monitoring and emissions quantification. | G10: China leads the world in estimated coal mine methane emissions. Underground coal mines account for nearly 70% of global Coal Mine Methane (CMM) emissions. Mitigation is possible through drainage and ventilation air. The main variables which affect gas emission rates in coal mining are in-situ gas content of coal seams, strength and reservoir properties of the strata surrounding longwall districts, working depth, panel dimensions, face advance rate and district age. Accounting for coal mine methane emissions is complicated and conducted in variable ways around the world. | H10: Coal | I10: Completed | J10: Assessing current Coal Mine Methane Emissions quantification literature to inform future studies | K10: Assessing current Coal Mine Methane Emissions quantification literature to inform future studies | M10: Stefan Schwietzke - Robert Field | N10: Stefan Schwietzke | O10: Desktop analysis | P10: 4 | Q10: IMEO
A11: 36067f76-d150-4489-b59c-e7d016ba0c76 | B11: North Sea Offshore Emissions: United Kingdom & Netherlands | D11: German Aerospace Center, Germany University of York, United Kingdom British Antarctic Survey, United Kingdom University of Cambridge, United Kingdom | E11: f08df46e-5e65-428c-9b95-282da81080e1 | F11: This study characterized methane emissions from several UK and Netherlands offshore production sites in the North Sea. Prior to International Methane Emissions Observatory (IMEO)'s offshore studies, there were few measurement-based | G11: The study compares measurement-based emissions estimates to a global gridded inventory, which breaks down emissions into a grid based on national emissions totals reported to the UNFCCC. It finds this inventory substantially underestimates emissions from the observed UK and Netherlands offshore facilities underscoring the limitations of global inventories for field-specific characterization. The study also compared emissions to the UK national point source inventory, finding some platforms emitted more than an order of magnitude higher than what was reported. However, operator- reported emissions, for the specific survey days aligned more closely with the study measurements. The median flaring combustion efficiency of 98.4 per cent was close to industry and government assumptions, but less efficient than in the Norwegian North Sea. | H11: Oil and Gas | I11: Completed | J11: North Sea offshore emissions: United Kingdom & Netherlands | M11: Mark Lunt | N11: Anke Roiger | O11: Measurement Campaign | P11: 1 | Q11: CCAC
A12: a56c0110-40cb-4314-a1c4-f657394afb91 | B12: North Sea Offshore Emissions: Norway | D12: Royal Holloway and Bedford New College, United Kingdom University of Manchester, United Kingdom | E12: 8801f22a-989e-4359-ae26-638366dcffda | F12: Prior to the UNEP’s International Methane Emissions Observatory (IMEO)’s offshore studies, there were few estimates of methane emissions from international oil and gas offshore infrastructure based on empirical data. Since offshore facility-level emissions can vary substantially over time, large and representative sampling is needed for meaningful comparisons with reported emissions. Such comparative data is necessary to build robust and comprehensive measurement, reporting and verification frameworks such as the one set up through UNEP’s Oil and Gas Methane Partnership 2.0 (OGMP 2.0). This study characterizes methane emissions from several offshore production sites in the North Sea. The IMEO team selected Norwegian infrastructure because the country is a major European oil and gas producer. It accounts for about 45 per cent of European oil and natural gas production over the past decade and its share of production is increasing. | G12: The measurements align with the data reported by the oil and gas operator. However, they are more than 40 per cent larger than a widely cited, globally gridded fossil fuel methane emission inventory based on United Nations Framework Convention on Climate Change (UNFCCC) country-level reports. | H12: Oil and Gas | I12: Completed | J12: North Sea offshore emissions: Norway | K12: North Sea offshore emissions: Norway | M12: Stefan Schwietzke | N12: Grant Allen | O12: Measurement Campaign | P12: 1 | Q12: CCAC
A13: 594a76e0-8b42-44e7-ac72-4d385fde96de | B13: Multi-Scale Measurements of Oil & Gas Production in Romania (ROMEO) | D13: Utrecht University, Netherlands | E13: d57ecf4e-49ec-4bec-83b1-78ff974f2792 | F13: Romania is a key oil and gas (O&G) producer in the EU and may be poised to increase production due to recent discoveries of significant natural gas reserves in the Black Sea. As a country that reports to the IPCC using simple emissions factors, Romania’s current emissions estimates lack measurement-based data. Inventory uncertainties pose challenges to prioritizing and implementing methane mitigation strategies to achieve country-level reductions. | G13: Measurements using a range of ground-based and aerial methods suggest Romania’s oil and gas sector emissions are significantly underreported. For oil production sites, total methane emission in the surveyed region alone (120 kt CH4 yr−1 with a range of 79–180 kt yr−1) are roughly 2.5 times larger than reported values for all of Romania in 2020. Measured oil production sites emit on average 5.4 kg CH4 h−1 per site (3.6 %–8.4 %, 95 % confidence interval), the third highest emission factor in comparison with US production regions for this type of infrastructure. 10% of sites are responsible for more than 70% of emissions, also a relatively high skewness compared to US regions, which represents an important mitigation priority. | H13: Oil and Gas | I13: Completed | J13: Romanian methane emissions from oil and gas (ROMEO project) | K13: Romanian methane emissions from oil and gas (ROMEO project) | M13: Stefan Schwietzke | N13: Thomas Roeckmann | O13: Measurement Campaign | P13: 1 | Q13: CCAC
A14: 80137543-d0a7-4e84-b241-5a0013b2e4b1 | B14: Emissions from Coal Seam Gas Production in Australia | D14: Airborne Research Australia, Australia University of New South Wales, Australia | E14: b262de7c-c521-434c-a5e2-cebee5ede085 | F14: Coal-seam gas production is an increasing but understudied phenomenon. It is important to understand the scale and scope of emissions from the practice to better manage them. This study provides data about emissions from coal-seam gas production and represents a critical first step in understanding other places where this production occurs. The Surat Basin is Australia’s largest coal seam gas (CSG) basin accounting for almost 20 per cent of Australian natural gas production, and is the focus of this study. | G14: This study found that measurement of dual isotopic signatures of methane can help to distinguish coal seam gas emissions from other individual source sectors in the Surat basin such as agriculture, waste and coal mine methane. CSG upstream sources emit about 0.4 per cent of produced gas, which is comparable to some onshore dry gas fields (Marcellus Shale in the US and Groningen field in The Netherlands). However, it is substantially smaller than other regions, especially those where oil is co-produced (wet gas). This study identified that water management/brine ponds associated with CSG may be a mitigation opportunity overlooked by existing bottom-up emissions inventories. | H14: Coal | I14: Completed | J14: Emissions from Coal Seam Gas Production in Australia | K14: Emissions from Coal Seam Gas Production in Australia | M14: Stefan Schwietzke | N14: Jorg Hacker | O14: Measurement Campaign | P14: 1 | Q14: CCAC
A15: 73c8c107-b3d8-4fac-a667-90dbbd7a1515 | B15: Australia Bowen Basin Pilot | D15: Airborne Research Australia, Australia | E15: b262de7c-c521-434c-a5e2-cebee5ede085 | F15: Australia is the world’s fifth largest coal producer and second largest exporter. Understanding the scale and location of its coal sector emissions is needed to assess total climate impact, target mitigation, and track progress. This pilot study aims to determine the feasibility of the aircraft mass balance approach for estimating emissions from large surface mines in Australia's Bowen Basin. Validating this approach is an important step for assessing the accuracy of emissions estimates from satellite and inventory methods in the coal sector. Satellite studies indicate that coal mine methane emissions in Queensland’s Bowen Basin are many times higher than emission inventories suggest. Meanwhile, the International Energy Agency’s 2023 Global Methane Tracker indicates Australia’s coal mine emissions reported through the United Nations Framework Convention on Climate Change may be underreported by 82 per cent. | G15: Determining whether the airborne mass balance approach can be successfully applied to accurately quantify methane emissions from open pit coal mines. | H15: Coal | I15: Completed | J15: Australia Bowen basin pilot | K15: Australia Bowen basin pilot | M15: Robert Field | N15: Jorg Hacker | O15: Measurement Campaign | P15: 1 | Q15: IMEO
A16: b88434be-0a7a-4755-b7e5-1e1522cce39e | B16: Verification of Coal Emissions with Top-Down Data in Australia | D16: University of Bremen, Germany | E16: 4c54c16a-1b6c-4521-b434-1de0ed4bdc59 | F16: Australia is the world’s fifth largest coal producer and second largest exporter. Understanding the scale and location of its coal sector emissions is needed to assess total climate impact, target mitigation, and track progress. This comprehensive study aims to deploy two independent airborne methods to determine methane emissions from both underground and large surface mines in Australia's Bowen Basin. Using precise but technically contrasting methods yields the high-quality empirical data needed to independently assess the accuracy of emissions estimates from satellite and inventory methods in the coal sector. Satellite studies indicate that coal mine methane emissions in Queensland’s Bowen Basin are many times higher than emission inventories suggest. Meanwhile, the International Energy Agency’s 2023 Global Methane Tracker indicates Australia’s coal mine emissions reported through the United Nations Framework Convention on Climate Change may be underreported by 82 per cent. | G16: Quantifying methane emissions from coal mines in Australia’s Bowen Basin. | H16: Coal | I16: Ongoing | J16: Validation of coal methane emissions with Top-Down data in Australia | K16: Validation of coal methane emissions with Top-Down data in Australia | M16: Robert Field | N16: Heinrich Bovensmann | O16: Measurement Campaign | P16: 1 | Q16: IMEO
A17: 7cd4458a-5a90-4aac-a80c-af3761d4389b | B17: Aerial & Ground-Based Measurements of Coal Methane Emissions in Poland | D17: AGH University of Science and Technology, Poland German Aerospace Center, Germany Technical University of Munich, Germany Swiss Federal Laboratories for Materials Science & Technology, Switzerland | E17: 4b346865-1fd5-4c11-86c0-a67bff8ff93b | F17: Poland is the world’s ninth largest coal producer and Europe’s leading producer of high-quality metallurgical coal, which is associated with higher levels of methane emissions especially when compared to lower quality lignite coal. Understanding the scale and location of its coal sector emissions is needed to assess climate impact, target mitigation and track progress. Satellite observation shows Poland is a major hotspot of methane emissions in Europe due to its high density of coal mining operations, particularly in the Upper Silesia Basin. The largest source of emissions in this region (~70 per cent) are estimated to be from underground mines’ ventilation shafts. A series of measurement campaigns have been designed to evaluate various atmospheric methods’ ability to estimate emissions from ventilation shafts to validate current emissions inventories, which are based on generic emissions factors and not direct measurement. The results will subsequently be compared with in-mine methane safety sensors synchronized with the aerial and ground-based methods to provide more granular verification. | G17: Quantifying emissions from metallurgical coal mining in Poland’s Upper Silesia Basin. | H17: Coal | I17: Ongoing | J17: Aerial & Ground-Based Measurements of Coal Methane Emissions in Poland | K17: Aerial & Ground-Based Measurements of Coal Methane Emissions in Poland | M17: Robert Field | N17: Jaroslaw Necki | O17: Measurement Campaign | P17: 1 | Q17: IMEO
A18: 5aa9a8f7-b0c5-4232-af4f-2715b0182952 | B18: Coal Studies Bottom-Up Global Coordination | D18: AGH University of Science and Technology, Poland | E18: 4b346865-1fd5-4c11-86c0-a67bff8ff93b | F18: Coal mining is a significant source of global methane emissions. Accurate data on the sector’s emissions is needed to track climate impact, target mitigation and assess progress. However, current inventories which apply generic emissions factors don’t align with available measurement data – signaling uncertainty that needs to be resolved. This requires validating approaches for measuring coal mine methane emissions. Ventilation shafts are a major source of coal mine emissions able to be observed by satellites, in addition to other airborne and ground-based methods and in-mine safety sensors. This offers a unique opportunity to compare data across these measurement techniques to validate their effectiveness and assess the best approaches for deployment. | G18: Results will assess approaches for estimating coal mine methane emissions across mine-based measurements, inventory calculations (UNFCCC) and satellite quantifications. | H18: Coal | I18: Ongoing | J18: Coal Studies Bottom-Up Global Coordination | K18: Coal Studies Bottom-Up Global Coordination | M18: Robert Field | N18: Jaroslaw Necki | O18: Measurement Campaign | P18: 1 | Q18: IMEO
A19: c9d3782b-661c-4b9d-aa7e-4aa29ccf2237 | B19: India abandoned coal mine study | D19: Indian Institute of Technology Bombay | E19: 93c3799b-3fe5-4dd9-b869-c402a1514bdc | F19: With the accelerating pace of coal mine closures globally, sustainable and accountable mine closure practices are becoming increasingly important. Inadequately sealed or unmanaged abandoned underground mines can continue to emit methane for years due to residual gas slowly migrating through fractures, boreholes, and permeable layers. Current national inventories often rely on default Tier-1 emission factors that do not account for site-specific variations or sealing status, potentially underestimating actual emissions. This study will apply a Tier-2 approach consistent with the IPCC’s 2019 Refinement for abandoned Indian underground coal mines to develop improved estimates by combining field measurements, mine status assessments, and comparisons with default emission factors. The results will support improved inventory accuracy and guide methane mitigation in the context of mine closure. | G19: In progress | H19: Coal | I19: Ongoing | J19: Building a Bottom-Up Methane Emission Inventory for Abandoned Underground Coal Mines in India | M19: Robert Field | N19: Vikram Vishal | O19: Measurement Campaign | Q19: IMEO
A20: b694b526-f335-4ebf-a0e8-04cc8b3106b9 | B20: Quantifying Coking Coal Mine Methane Emissions Using Multiple Surface and Satellite Observations | D20: China University of Mining Technology | E20: 4d2561a3-9703-40cb-b06b-e98bb5205867 | H20: Coal | I20: Ongoing | J20: Quantifying Coking CMM | M20: Robert Field | N20: Kai Qin | O20: Measurement Campaign | Q20: IMEO
A21: a70b91d9-36aa-4cae-9d4b-0c76c1390303 | B21: Baseline Scoping Study of Emissions in Colombia | D21: Universidad Nacional de Colombia, Colombia | E21: 339835e0-2d02-47af-8f95-3e2b954c6bdf | F21: Colombia, like many countries, faces challenges setting effective methane reduction targets and tracking progress due to a lack of measurement-based emissions data across sectors. The country has already demonstrated significant leadership on methane through regulatory efforts, but better measurement data is needed to ensure mitigation efforts are targeted and effective. | G21: This effort will design a suitable measurement-based strategy for quantification of prioritized anthropogenic methane emissions in Colombia. The next step, a full Baseline Study, would estimate total methane emissions nationally and across sectors and can inform national greenhouse gas inventories, reveal areas to prioritize emission reduction, and help discover the sources of discrepancies. | H21: Multisector | I21: Completed | J21: Baseline Scoping Study of Emissions in Colombia | K21: Baseline Scoping Study of Emissions in Colombia | M21: Nataly Velandia | N21: Rodrigo Jimenez | O21: Desktop analysis | P21: 4 | Q21: IMEO
A22: e7cecf66-076a-4b5a-8cf5-658f497a904b | B22: Baseline Study of Emissions in Colombia - Inventory synthesis and communications | D22: Universidad Nacional de Colombia, Colombia | E22: 339835e0-2d02-47af-8f95-3e2b954c6bdf | H22: Multisector | I22: Upcoming | M22: Nataly Velandia | N22: Rodrigo Jimenez | O22: Measurement Campaign | P22: 4 | Q22: IMEO
A23: d27f9459-c1de-4abb-b875-0a245534e947 | B23: LNG Reconciliation Study | D23: National Physical Laboratory, United Kingdom | E23: 92fd7e5a-3de7-4b6d-98e9-e921991f1724 | F23: Liquified Natural Gas (LNG) has emerged as a major import and export product around the world, with the IEA projecting over 250 billion cubic meters of liquefaction capacity to be brought online annually through 2030. However, amid this growth there remains significant uncertainty surrounding methane emissions from LNG facilities (liquefaction, regasification and shipping). | G23: To enable more accurate assessment of LNG emissions, this study attempts to reconcile emissions estimates obtained from two independent measurement approaches at two LNG liquefaction plants. The reconciliation will compare emissions estimated from different measurement approaches and explore whether the contribution of emissions from different known emission points in a site are representative of all sources within the LNG facility when scaled by production data. | H23: Oil and Gas | I23: Completed | J23: Reconciling LNG emissions | K23: Reconciling LNG emissions | M23: Mark Lunt | N23: Rod Robinson | O23: Desktop analysis | P23: 1 | Q23: IMEO
A24: 12715187-0935-4ad8-bd8d-42ae4c8aa233 | B24: Characterization of LNG Facilities in Australia | D24: Airborne Research Australia, Australia | E24: b262de7c-c521-434c-a5e2-cebee5ede085 | F24: Liquified Natural Gas (LNG) has emerged as a major import and export product around the world, with the IEA projecting over 250 billion cubic meters of liquefaction capacity to be brought online annually through 2030. However, amid this growth there remains significant uncertainty surrounding methane emissions from LNG facilities (liquefaction, regasification and shipping). This study aims to conduct facility-level airborne measurements of all onshore LNG liquefaction facilities in Australia, a major global LNG exporter.. The results will improve knowledge of industry-wide emissions and emission intensities while identifying common factors responsible for varying levels of emissions. | G24: Multiple measurement-based quantifications at each onshore LNG liquefaction facility in Australia will derive emission estimates under a range of operating conditions. | H24: Oil and Gas | I24: Completed | J24: Measurement of LNG Facility emissions in Australia | K24: Measurement of LNG Facility emissions in Australia | M24: Mark Lunt | N24: Jorg Hacker | O24: Measurement Campaign | P24: 1 | Q24: IMEO
A25: c6c4d345-90e1-4dc3-b9cd-3b0c6354e166 | B25: Aerial Measurements of Emissions in Oman | D25: German Aerospace Center, Germany AGH University of Science and Technology, Poland | E25: f08df46e-5e65-428c-9b95-282da81080e1 | F25: Prior to this research, there has been no independent, in-depth study of oil and gas methane emissions on the Arabian Peninsula. To expand measurement-based understanding of emissions across sectors, a component on waste sector emissions was added to the oil and gas campaign. | G25: The study will assess oil and gas site-level emissions and sourcelevel distribution via aerial and ground-based methane surveys. | H25: Multisector | I25: Ongoing | J25: Aerial Measurements of Emissions in Oman | K25: Aerial Measurements of Emissions in Oman | M25: Mark Lunt | N25: Heidi Huntrieser | O25: Measurement Campaign | P25: 4 | Q25: IMEO
A26: d1a75482-6096-4292-a00c-30742826c32d | B26: Urban Controlled Methane Release Studies - Blind Release Rates and Locations | D26: Nanjing University China | E26: 30ee24bd-56bb-48fb-a00c-44554940b7e9 | F26: The detection and quantification of urban methane emissions using mobile measurements at ground level is a widely applied technique that has moved beyond the research sphere to commercial operation. However, there has been limited validation of the measurement technologies and approaches used to detect and quantify emissions in such settings. This study aims to address that by conducting a blind controlled release test within a real-world urban environment. | G26: In progress | H26: Oil and Gas | I26: Ongoing | J26: Urban Controlled Methane release studies | M26: Mark Lunt | N26: Huilin Chen | O26: Controlled release | P26: 2 | Q26: IMEO
A27: a6a9466c-4c54-4d66-86da-54f81266ac95 | B27: Feasibility Analysis For IMEO dedicated helicopter towed sensor platform | D27: Technical University of Braunschweig | E27: dfea752b-ebb7-4243-b4ba-b2199764c2fb | H27: Multisector | I27: Upcoming | M27: Mark Lunt | N27: Astrid Lampert | O27: Desktop analysis | Q27: IMEO
A28: f9d50385-5ddc-4996-a752-414616e08989 | B28: Measurement-Based Characterization of Emissions from Canadian Landfills | D28: St Francis University, United States | E28: df72143d-ada4-43a7-8812-fad702be3ec9 | F28: The waste sector is a significant source of methane emissions and measurement data is needed to assess the accuracy of emissions modelling that often forms the basis of policy decisions and mitigation action. Canada has committed to developing and implementing regulations to halve methane emissions from large municipal solid waste landfills from 2019 levels by 2030. | G28: Modelled landfill emissions for national reporting overestimated methane emissions by 1.4x relative to the measurements obtained for Canadian landfills. | H28: Waste & Wastewater | I28: Completed | J28: Measuring emissions from Canadian landfills | K28: Measuring emissions from Canadian landfills | M28: Marci Baranski | N28: Chelsie Hall | O28: Measurement Campaign | P28: 2 | Q28: IMEO
A29: f1e22d36-eae5-4e1c-b905-5330488094cc | B29: Measurement Campaign in Azerbaijan | D29: German Aerospace Center, Germany Environmental Defense Fund, United States | E29: f08df46e-5e65-428c-9b95-282da81080e1 | F29: There is currently no independent empirical data to derive representative emission estimates of oil and gas sources from former Soviet Union states apart from a limited number of point sources. Understanding oil and gas emissions is particularly salient given the country’s gas exports to markets such as the EU. The study would also provide independent data to support implementation of new EU methane legislation which requires the assessment of emissions associated with oil and gas imports. Azerbaijan is also host to some of the largest methane emitting mud volcanoes, a potentially significant natural methane source globally. The study will also measure methane emissions from this source. Given that methane from oil and gas and mud volcanoes have a similar chemical fingerprint, the study will help better apportion global total methane emissions into oil and gas sources versus mud volcanoes. | G29: This study will determine the magnitude and locations of methane emissions from several oil and gas operators, covering both national and international oil companies, as well as from mud volcanoes. | H29: Multisector | I29: Ongoing | J29: Measurement campaign in Azerbaijan | K29: Measurement campaign in Azerbaijan | M29: Malika Menoud - Andreea Calcan | N29: Anke Roiger | O29: Measurement Campaign | P29: 3 | Q29: CCAC
A30: 860c8019-d3a8-4216-be13-9c85f2265a36 | B30: Quantification of Emissions from Floating Production Storage Offloading Site | D30: University of York, United Kingdom | E30: d8a670b7-8563-4957-97bf-9c46f9480e34 | F30: Floating production storage and offloading (FPSO) vessels are widely used in the global offshore oil industry to process hydrocarbons and store oil before it is offloaded to a shuttle tanker for export. There is currently no direct measurement data for FPSOs' emissions and there is a lack of multi-scale offshore measurements in existing scientific literature from oil and gas facilities. | G30: This work will compare methane emission quantifications of a FPSO site before, after and during an offloading event at Glen Lyon, Shetland using aerial, drone and bottom-up quantification methods. | H30: Oil and Gas | I30: Ongoing | J30: Quantification of emissions from floating production storage offloading site | K30: Quantification of emissions from floating production storage offloading site | M30: James France | N30: James Lee | O30: Measurement Campaign | P30: 3 | Q30: IMEO
A31: 29dcb255-dd1a-4467-9f44-09fac0a50f70 | B31: Global Analysis of Emissions from Abandoned Wells | D31: McGill University, Canada | E31: 109f7f51-a57f-4d02-8778-4cfb99f539ec | F31: Globally, there are millions of abandoned oil and gas wells but only a very small number of methane emissions measurements of them exist outside North America. These wells have the potential to collectively emit significant methane emissions, but additional data is needed to understand their impact in regions beyond North America so that inventories can effectively account for them and mitigation resources can be effectively deployed. | G31: This work will provide data on abandoned well emissions from regions around the world and reconcile currently available data to provide an estimate of abandoned wells’ total emissions. The results will contribute to understanding the conditions that lead to high-emitting abandoned oil and gas wells. | H31: Oil and Gas | I31: Ongoing | J31: Global analysis of emissions from abandoned wells | K31: Global analysis of emissions from abandoned wells | M31: James France | N31: Mary Kang | O31: Measurement Campaign | P31: 3 | Q31: Both
A32: 38918a12-b6f5-41c7-9d2d-b64291ca87eb | B32: Validation of Methane Quantification Technologies | D32: Stanford University, United States | E32: 5e3558b7-6b43-46aa-8130-01e66830ac42 | F32: Accurate quantification of methane emissions is crucial for both tracking mitigation and informing regulatory decision making. Therefore, methodologies claiming to quantify methane emissions require independent and rigorous validation to give confidence and reassurance that accurate reporting of emissions through measurement is viable. The research being undertaken is intended to evaluate and demonstrate these capabilities and their ability to support the EU’s methane strategy and broader goals under the Global Methane Pledge. | G32: The study will assess the accuracy of various methane detection technologies. | H32: Oil and Gas | I32: Ongoing | J32: Validation of methane quantification technologies | K32: Validation of methane quantification technologies | M32: James France | N32: Adam Brandt | O32: Controlled release | P32: 2 | Q32: IMEO
A33: 2ee1bd3f-9ea0-4b14-968c-abf6d7e6a226 | B33: Local Distribution Studies | D33: Technical University of Munich, Germany University of Groningen, Netherlands University of Toronto, Canada Autonomous University of Barcelona, Spain Université de Versailles Saint-Quentin-en-Yvelines, France Environment and Climate Change Canada, Canada | E33: e7f2b433-cd11-416a-ae91-58634409cbb9 | F33: Previously, there was a lack of open, empirical data characterizing emissions from local distribution systems in Europe in comparison to systems elsewhere. These systems are important in the EU as they are a major source of nonimported oil and gas methane emissions. This study assessed emissions from a number of European (and Toronto) distribution systems and compared them to emissions from cities in the US and Canada. This set of studies also incorporated measurements of midstream facilities near sampling regions. | G33: This study provided evidence of methane leaks that can be mitigated and suggestions to target street-level methane emissions on natural gas distribution networks, sewage systems and furnaces. The study found that the waste sector is the largest methane emitter in the Toronto area. It also found that engineered waterways (not currently in inventories) may be a significant source. Based on the measurements collected, compressor stations and leaks from natural gas distribution network also contribute to emissions, though more information/ measurements are needed to fully characterize. The study demonstrated that not all methane leaks at ground level are gas distribution network infrastructure leaks. Large emissions also originate from the sewage network. This carries implications for measuring methane without also measuring co-emitted species for source identification – methane emissions may have been mis-categorized otherwise. In-building methane emissions (e.g., from stoves or boilers) may be missed in mobile street-level measurements. This study found strong indications of a large biogenic source of methane in Hamburg, correlated with rising tide of its river estuary. The addition of river emissions improved the performance of emissions modeling. The study found that all cities have a spectrum of small, medium and large methane sources in their domain. The emission rates found follow a heavy-tailed distribution, and the top 10 per cent of emitters account for 60–80 per cent of total emissions, which implies that strategic repair planning could help reduce emissions quickly. Furthermore, while cities with larger reported emissions were found to generally also have larger observed emissions, there are clear discrepancies between observation-based and inventory-based emission estimates for our 12 cities. | H33: Oil and Gas | I33: Completed | J33: Local distribution studies | K33: Local distribution studies | M33: James France | N33: Felix Vogel | O33: Measurement Campaign | P33: 1 | Q33: CCAC
A34: 55b560ec-1523-4186-a81b-043a92b4b04b | B34: Satellite-Based Detection and Quantification of Offshore Plumes | D34: València Polytechnic University, Spain | E34: b1e7baf4-b7a1-4949-8286-9b177ed06131 | F34: The study aims to further facilitate the implementation of offshore plume detection methods for use in IMEO’s Methane Alert and Response System (MARS), which notifies governments and companies of major emission events detected by satellites. Offshore oil and gas production is a sector with significant emissions uncertainty. Enabling improved satellite monitoring of offshore sites is necessary to enable better understanding and mitigation of emissions. | G34: The study will determine which offshore areas of the world are eligible to be monitored with multispectral satellites and identify the angular requirements to detect an offshore emission with hyperspectral satellites. | H34: Oil and Gas | I34: Ongoing | J34: Satellite-based detection and quantification of offshore plumes | K34: Satellite-based detection and quantification of offshore plumes | M34: Itziar Irakulis - Alba Lorente | N34: Luis Guanter | O34: Remote Sensing | P34: 3 | Q34: IMEO
A35: 29df8f34-6a80-4e90-bce4-f22613bc94ee | B35: TROPOMI-Based Quantification of Regional Emissions | D35: Netherlands Institute for Space Research, Netherlands | E35: fd165b68-89ef-4b22-bb12-a019eb5e1ae7 | F35: Individual countries report their emissions to the United Nations Framework Convention on Climate Change (UNFCCC) and these provide targets for Nationally Determined Contributions (NDCs) to climate change mitigation under the Paris Agreement. However, these inventories have high uncertainty in assessing emissions at the regional/national scale. Satellites can decrease this uncertainty by providing global monitoring of emissions. This study will generate a worldwide quantification of total methane emissions from oil, gas, and coal production on national and basin scales by inversion of multi-year TROPOMI observations with prior point source and infrastructure information. | G35: This study will quantify regional (national and basin scale) methane emissions from oil and gas production worldwide by timedependent inversion of TROPOMI observations at 25-50 km resolution. The results (including error characterization) will be used to evaluate the national emission reports to the UNFCCC, thereby enabling the formulation of improved NDCs | H35: Multisector | I35: Completed | J35: TROPOMI-based worldwide characterization of emissions | K35: TROPOMI-based worldwide characterization of emissions | M35: Itziar Irakulis - Alba Lorente | N35: Ilse Aben | O35: Remote Sensing | P35: 2 | Q35: CCAC
A36: 1923b621-10ef-4a5b-8480-420078fe65dc | B36: Continuous Monitoring of Methane Emissions with TROPOMI Satellite Observations in Support of IMEO | D36: Harvard University, United States | E36: b85535b7-577a-4f54-b447-68d75847bf3c | F36: Methane-monitoring satellites offer a valuable tool to track emissions, target mitigation and assess progress. The European Space Agency’s TROPOspheric Monitoring Instrument (TROPOMI) on board the Sentinel-5P satellite is an area mapping instrument that surveys larger regions at a time for methane emissions. There is an opportunity to integrate data from other satellite missions which have higher resolution over smaller areas (point source mappers) to refine insights and provide more granular and actionable methane data. The Integrated Methane Inversion (IMI) provides a ready-made open access tool to make these integrated observations available to users. | G36: The study will quantify high-frequency (weekly, monthly) methane emissions from satellite measurements, allowing the identification of factors driving the variability of the emissions. The study underscores the potential of satellite-based remote sensing as a tool for accurate, continuous and large-scale monitoring of methane emissions. | H36: Multisector | I36: Ongoing | J36: Continuous Monitoring of Methane Emissions with TROPOMI Satellite Observations | K36: Continuous Monitoring of Methane Emissions with TROPOMI Satellite Observations | M36: Itziar Irakulis - Alba Lorente | N36: Daniel Jacob | O36: Remote Sensing | P36: 2 | Q36: IMEO
A37: 9b2fe3ff-1709-4a42-81d7-82c5f924e6a0 | B37: TROPOMI-Based Worldwide Characterization of Emissions | D37: Harvard University, United States | E37: b85535b7-577a-4f54-b447-68d75847bf3c | F37: Individual countries report their emissions to the United Nations Framework Convention on Climate Change (UNFCCC) and these provide targets for Nationally Determined Contributions (NDCs) to climate change mitigation under the Paris Agreement. However, these inventories have high uncertainty in assessing emissions at the regional/national scale. Satellites can decrease this uncertainty by providing global monitoring of emissions. This study will generate a worldwide quantification of total methane emissions from oil, gas, and coal production on national and basin scales by inversion of multi-year TROPOMI observations with prior point source and infrastructure information. | G37: This study will quantify regional (national and basin scale) methane emissions from the oil and gas production worldwide by time-dependent inversion of TROPOMI observations at 25-50 km resolution. The results (including error characterization) will be used to evaluate the national emission reports to the UNFCCC, thereby enabling the formulation of improved NDCs. | H37: Multisector | I37: Ongoing | J37: TROPOMI-based worldwide characterization of emissions | M37: Itziar Irakulis - Alba Lorente | N37: Daniel Jacob | O37: Remote Sensing | P37: 2 | Q37: IMEO
A38: 9a8309bb-73ed-46ff-b5a6-ff6578cf8a50 | B38: MARS contract | D38: SRON | E38: fd165b68-89ef-4b22-bb12-a019eb5e1ae7 | F38: Satellite-based methods and capabilities for methane detection are rapidly evolving, in favor of higher transparency and accuracy in emissions estimates across different sectors. In particular, emissions from open-pit coal mines remain challenging due to their diffuse nature over large areas, requiring the development of accurate and reliable methods to obtain estimates based on empirical measurements. Satellite data enable replication and extrapolation of these methods across the globe quickly and at lower cost compared to other measurement approaches. On the other hand, satellite sensors already in operation with high revisit frequency and the potential to detect methane, such as VIIRS sensors, open up the possibility of more frequent methane emissions monitoring at different times of the day. However, as these sensors were not initially designed to detect methane, their low sensitivity requires careful processing and specific methods to extract methane emissions data. | G38: The study to assess the potential of VIIRS to detect point-source methane emissions demonstrated that this sensor can retrieve atmospheric methane enhancements with high spatial resolution and effectively track super-emitter events multiple times per day. Combining VIIRS and TROPOMI observations enables both detection and direct source attribution, while allowing for cross-validation between instruments. Furthermore, integrating the three VIIRS satellites with Sentinel-3 SLSTR data provides global coverage at least four times per day, offering valuable insight into short-lived and transient methane emissions. Overall, the study establishes the basis for a daily, global, and operational methane monitoring system. The study, focused on estimating methane emissions from this type of mine, aims to develop the methodology necessary to obtain emission estimates based on data from the TROPOMI sensor aboard the Sentinel-5P satellite. It will provide results for three large coal mines in three different countries. The developed methodology is expected to be extrapolable to other mines worldwide, offering more reliable and accurate emission estimates and improving those estimates only based on emission factors. | H38: Multisector | I38: Ongoing | J38: MARS support with Satellite Methane detection methods development | M38: Itziar Irakulis - Alba Lorente | N38: Ilse Aben | O38: Remote Sensing | P38: 2 | Q38: IMEO
A39: 338c51db-d03a-4384-87e3-bc177143bbf5 | B39: Multi-Scale Measurements in Colombia | D39: Carleton University, Canada | E39: 561bf82a-557c-4655-958c-8684e9d78281 | F39: There are few empirically-based estimates of methane emissions from South American oil and gas producing countries. This study will combine measurements at regional, site and source level to characterize emissions from oil and gas production in Colombia. | G39: This study will combine measurements at regional, site and source level to characterize emissions from oil and gas production in Colombia. | H39: Multisector | I39: Ongoing | J39: Multi-scale measurements in Colombia | K39: Multi-scale measurements in Colombia | M39: Daniel Zavala - Andreea Calcan | N39: Matthew Johnson | O39: Measurement Campaign | P39: 1 | Q39: IMEO
A40: 70f2024b-e279-4d03-9ca1-d8c1be5c09b0 | B40: Emissions from Offshore Production in the United States Gulf of Mexico | D40: University of Michigan, United States | E40: 69e5ee87-975c-46ec-b3dd-7acbd626fac3 | F40: Before this study, there were few to no empirical-based estimates of methane emissions from oil and gas offshore infrastructure. This study, undertaken in the US, is the first to provide offshore emissions assessment via direct measurement. This measurement data is necessary to understand the amount, locations, and sources of emissions to accurately assess and mitigate them. | G40: The study highlights that offshore production in shallow waters emits at higher rates than that in deepwater, as well as indicates the significant contribution of super-emitters to overall emissions. The new estimates are consistent with the EPA inventory in deep water but appear higher for shallow water. The study’s inventory, informed by regional airborne estimates, reports emissions to be twice as high as reported by the Environmental Protection Agency Greenhouse Gas Inventory (GHGI) with regional airborne estimates. Measurements taken from ships of over 100 offshore sites found emission rates were highly variable – but the distribution is heavily skewed with the top two emitters accounting for 20 per cent of the total methane emissions. Ship-based measurements agreed that emissions appear greater from shallow water sites | H40: Oil and Gas | I40: Completed | J40: Emissions from offshore production in the US Gulf of Mexico | K40: Emissions from offshore production in the US Gulf of Mexico | M40: Daniel Zavala | O40: Measurement Campaign | P40: 1 | Q40: CCAC
...

Sheet Paper_ID
A1: id_paper | B1: id_study | C1: paper_title | D1: first_author | E1: paper_short_title | F1: doi | G1: publication_date | H1: collection_method | I1: paper_status | J1: type_of_data | K1: paper_key_findings | L1: paper_imeo_received | M1: paper_soc_reviewed | N1: journal_name | O1: in_house_study | P1: contact_name_imeo_author | Q1: flag_location
A2: db509759-4f90-4df1-9c2b-5951a791810f | B2: 12715187-0935-4ad8-bd8d-42ae4c8aa233 | C2: Isotope bag sampler methods | D2: Wolfgang Junkermann | H2: Airborne | I2: Manuscript Drafting | J2: Empirical | O2: No | Q2: Yes
A3: 949eb05e-57e9-46c8-af70-4bf5190114ad | B3: 12715187-0935-4ad8-bd8d-42ae4c8aa233 | C3: An evaluation of airborne mass balance and tracer correlation approaches to estimate site-level CH4 emissions from LNG facilities using CO2 as a tracer of opportunity | D3: Lunt et al., 2025 | E3: Tracer correlation at LNG facilities | F3: https://doi.org/10.5194/egusphere-2025-1926 | G3: 45911 | H3: Airborne | I3: Published | J3: Empirical | L3: 45689 | M3: 45717 | N3: Atmospheric Measurement Techniques | O3: Yes | P3: Mark Lunt | Q3: Yes
A4: afccf0a5-d14b-4906-bc65-674875539e01 | B4: 12715187-0935-4ad8-bd8d-42ae4c8aa233 | C4: Characterization of methane emissions from LNG liquefaction facilities in Australia via airborne measurements | D4: Jorg Hacker | H4: Airborne | I4: Manuscript Drafting | J4: Empirical | Q4: No
A5: 38c928db-e63f-4c5a-9e3f-a1e3887a8fb5 | B5: 1370995b-5032-4a4b-87d5-1a6fd7df10e1 | C5: The Efficacy of LDAR Programs in Practice | D5: Shona Wilde | E5: The Efficacy of LDAR Programs in Practice | H5: Airborne | I5: Submitted to Journal | J5: Empirical | L5: 45627 | M5: 45717 | O5: No | Q5: No
A6: fd6cb0ce-cf68-4d2f-a8cd-9c403cbeba26 | B6: 1370995b-5032-4a4b-87d5-1a6fd7df10e1 | C6: Catalytic Heaters at Oil and Gas Sites May be a Significant yet Overlooked Seasonal Source of Methane Emissions | D6: Festa-Bianchet et al. 2024 | E6: Catalytic heaters methane emissions | F6: https://doi.org/10.1021/acs.estlett.4c00453 | G6: 45516 | H6: Ground-based static | I6: Published | J6: Empirical | N6: Environmental Science & Technology (ES&T) | O6: No | P6: None | Q6: Yes
A7: 36651729-c0d4-499f-a46f-9e8a91b27d47 | B7: 1923b621-10ef-4a5b-8480-420078fe65dc | C7: Global Rice Paddy Inventory (GRPI): a high-resolution inventory of methane emissions from rice agriculture based on Landsat satellite inundation data | D7: Chen et al., 2024 | E7: Global rice paddy inventory | F7: https://doi.org/10.1029/2024EF005479 | G7: 45773 | H7: Satellite | I7: Published | J7: Empirical | L7: 45505 | N7: Earth's Future | O7: No | P7: None | Q7: No
A8: c225135b-8c23-46ac-84a4-54def66f9a94 | B8: 25e348c0-c485-4f68-b882-c0d489e85e86 | C8: Airborne quantification of Angolan offshore oil and gas methane emissions | D8: Fiehn et al., 2025 | E8: Angolan offshore oil and gas methane emissions | F8: https://doi.org/10.5194/egusphere-2025-635 | H8: Airborne | I8: Submitted to Journal | J8: Empirical | L8: 45505 | M8: 45658 | N8: Atmospheric Chemistry and Physics | O8: No | P8: None | Q8: Yes
A9: 23d195b9-f63b-452d-a552-4f028a3a037a | B9: 25e348c0-c485-4f68-b882-c0d489e85e86 | C9: Airborne quantification of Angolan offshore oil and gas methane emissions | D9: Alina Fiehn | F9: https://doi.org/10.5194/egusphere-2025-635 | H9: Airborne | I9: Submitted to Journal | J9: Empirical | N9: Atmospheric Chemistry and Physics | O9: No | P9: None | Q9: Yes
A10: a452377e-ced5-41b4-a1c8-ece961eb6dfa | B10: 29dcb255-dd1a-4467-9f44-09fac0a50f70 | C10: Methane Emission estimates from Italian Abandoned oil and gas wells | D10: Monia Prosecci | H10: Ground-based static | I10: SOC review | J10: Empirical | L10: 45778 | O10: No | Q10: Yes
A11: 7484fd90-a1c7-4f92-a6c0-1fbed4eb21c9 | B11: 29dcb255-dd1a-4467-9f44-09fac0a50f70 | C11: Overview of methane emissions from global abandoned oil and gas wells | D11: Mary Kang (or Student of Mary) | H11: Ground-based static | I11: Manuscript Drafting | J11: Empirical | Q11: No
A12: 0fa404ea-f6b5-4895-8153-16c9b8c9934d | B12: 29dcb255-dd1a-4467-9f44-09fac0a50f70 | C12: Long-term emission of methane and ethane to the atmosphere from hybrid natural seepage and well leakage in the Sărmășel gas field (Romania) | D12: Eduard Ghiorghiu | E12: Methane emission estimations from gas fiel in Romania | H12: Ground-based static | I12: Submitted to Journal | J12: Empirical | L12: 45839 | N12: Applied geochemistry | O12: No | Q12: Yes
A13: af6ca6c2-4bf5-4e95-90a8-c5598daa7803 | B13: 29dcb255-dd1a-4467-9f44-09fac0a50f70 | C13: Methane Emission estimates from Colombian Abandoned oil and gas wells | H13: Ground-based static | I13: Project Initiation | J13: Empirical | Q13: Yes
A14: 5dd2146f-5fc1-4667-a931-2c507a40f176 | B14: 29dcb255-dd1a-4467-9f44-09fac0a50f70 | C14: Methane Emission estimates from German Abandoned oil and gas wells | H14: Ground-based static | I14: Project Initiation | J14: Empirical | Q14: Yes
A15: 2bd022e0-8b29-45bb-8fbd-1311296b23aa | B15: 29df8f34-6a80-4e90-bce4-f22613bc94ee | C15: Assessing the Relative Importance of Satellite-Detected Methane Superemitters in Quantifying Total Emissions for Oil and Gas Production Areas in Algeria | D15: Naus et al., 2023 | E15: Satellite-Detected methane supperemitters in Algeria | F15: https://doi.org/10.1021/acs.est.3c04746 | G15: 45243 | H15: Satellite | I15: Published | J15: Empirical | K15: Top-down analysis indicates that a larger fraction of Algeria’s methane emissions come from oil production than national reporting suggests. Roughly a quarter of emissions come from super-emitters in the Hassi R’Mel Basin and and half come from the Hassi Messaoud basin. | N15: Environmental Science & Technology (ES&T) | O15: No | P15: Itziar Irakulis | Q15: Yes
A16: e431bb4a-1a49-494d-841f-9cac66d149dc | B16: 29df8f34-6a80-4e90-bce4-f22613bc94ee | C16: Assessing methane emissions from collapsing Venezuelan oil production using TROPOMI | D16: Nathan et al., 2024 | E16: Methane emissions from Venezuelan oil production | F16: https://doi.org/10.5194/acp-24-6845-2024 | G16: 45456 | H16: Satellite | I16: Published | J16: Empirical | N16: Atmospheric Chemistry and Physics | O16: No | P16: Alba Lorente | Q16: Yes
A17: d84f77e2-328a-4bbf-ad1f-59c35e5c47c7 | B17: 29df8f34-6a80-4e90-bce4-f22613bc94ee | C17: Daily global methane super-emitter detection and source identification with sub-daily tracking | D17: De Jong et al., 2025 | E17: Super-Emitter Detection and Source Identification | F17: https://doi.org/10.1029/2024GL111824 | G17: 45771 | H17: Satellite | I17: Published | J17: Empirical | N17: Geophysical Research Letters | O17: No | P17: Itziar Irakulis | Q17: No
A18: 0b349592-686d-4de2-b26c-becc6511c141 | B18: 2c366808-4f57-4ca6-a4f6-53f027e06258 | H18: Desktop | I18: Analysis Ongoing | J18: Empirical | Q18: Yes
